<mujoco model="cobot_magic">
    <compiler angle="radian" meshdir="meshes/" />
    <asset>
        <mesh name="base_link" file="meshes/base_link.STL" />
        <mesh name="box1_Link" file="meshes/box1_Link.STL" />
        <mesh name="box2_Link" file="meshes/box2_Link.STL" />
        <mesh name="link1" file="meshes/link1.STL" />
        <mesh name="link2" file="meshes/link2.STL" />
        <mesh name="link3" file="meshes/link3.STL" />
        <mesh name="link4" file="meshes/link4.STL" />
        <mesh name="link5" file="meshes/link5.STL" />
        <mesh name="link6" file="meshes/link6.STL" />
        <mesh name="dabai" file="meshes/dabai.STL" />
    </asset>

    <worldbody>
        <body name="body" pos="0 0 0">
            <body name="robot" pos="0 0 0">
                <!-- robot view -->
                <camera mode="fixed" name="robotview" pos="1.0 0 0.4" quat="0.653 0.271 0.271 0.653" />
                <inertial diaginertia="0 0 0" mass="0" pos="0 0 0" />
                <!-- mount attached here -->
                <geom pos="0 0 0.155" euler="0 0 0" type="mesh" group="1" density="7.85"
                    rgba="0.79216 0.81961 0.93333 1" mesh="box2_Link" />
                <geom pos="0.2 -0.01 0.863" euler="0 1.57 1.57" type="mesh" group="1" density="2.83"
                    rgba="0.898039 0.917647 0.929412 1" mesh="dabai" />
                <camera name="main" pos="0.2079 -0.01983 0.863" euler="0 -1.57 -1.57" fovy="41"
                    mode="fixed" />
                <geom pos="0.233 0.3 0.761" type="mesh" group="1" density="2.83"
                    rgba="0.75294 0.75294 0.75294 1"
                    mesh="base_link" />
                <geom pos="0.234 -0.303 0.761" type="mesh" group="1" density="2.83"
                    rgba="0.75294 0.75294 0.75294 1"
                    mesh="base_link" />
                <body name="fr_link1" pos="0.234 -0.303 0.8212">
                    <site name="right_center" pos="0 0 0" size="0.01" rgba="1 0.3 0.3 1" group="2" />
                    <inertial pos="0.00609525 -0.00429682 0.017959"
                        quat="0.680193 0.680193 -0.193229 0.193229" mass="0.0608351"
                        diaginertia="8.61803e-05 6.38197e-05 3e-05" />
                    <joint name="fr_joint1" pos="0 0 0" axis="0 0 1" limited="true"
                        range="-3.14158 3.14158"
                        damping="0.1" />
                    <geom type="mesh" group="1" density="2.83" rgba="0.752941 0.752941 0.752941 1"
                        mesh="link1" />
                    <body name="fr_link2" pos="0.02 0 0.0402">
                        <inertial pos="-0.132382 0.00220381 0.00011179" quat="0 0.706195 0 0.708017"
                            mass="1.07333" diaginertia="0.0160201 0.01596 0.000499897" />
                        <joint name="fr_joint2" pos="0 0 0" axis="0 1 0" limited="true"
                            range="0 3.14158"
                            damping="0.1" />
                        <geom type="mesh" group="1" density="2.83"
                            rgba="0.752941 0.752941 0.752941 1"
                            mesh="link2" />
                        <body name="fr_link3" pos="-0.264 0 0" quat="-3.67321e-06 -1 0 0">
                            <inertial pos="0.187203 -0.000305676 -0.0514833"
                                quat="0.269626 0.618013 0.251786 0.694238" mass="0.499405"
                                diaginertia="0.00388848 0.00385541 0.000286113" />
                            <joint name="fr_joint3" pos="0 0 0" axis="0 1 0" limited="true"
                                range="0 3.14158"
                                damping="0.1" />
                            <geom type="mesh" group="1" density="2.83"
                                rgba="0.752941 0.752941 0.752941 1"
                                mesh="link3" />
                            <body name="fr_link4" pos="0.245 0 -0.056">
                                <inertial pos="0.0388885 0.00295169 -0.0353283"
                                    quat="0.913916 -0.0752199 0.315785 -0.243679" mass="0.0809713"
                                    diaginertia="0.000184798 0.000152076 5.31251e-05" />
                                <joint name="fr_joint4" pos="0 0 0" axis="0 1 0" limited="true"
                                    range="-2 1.67" damping="0.1" />
                                <geom type="mesh" group="1" density="2.83"
                                    rgba="0.898039 0.917647 0.929412 1"
                                    mesh="link4" />
                                <body name="fr_link5" pos="0.06575 -0.001 -0.0825">
                                    <inertial pos="0.00289957 3.15827e-05 0.0526189"
                                        quat="0.998829 0 -0.0483866 0" mass="0.602357"
                                        diaginertia="0.000724856 0.00069 0.000205144" />
                                    <joint name="fr_joint5" pos="0 0 0" axis="0 0 1" limited="true"
                                        range="-1.5708 1.5708" damping="0.1" />
                                    <geom type="mesh" group="1" density="2.83"
                                        rgba="0.752941 0.752941 0.752941 1"
                                        mesh="link5" />
                                    <body name="fr_link6" pos="0.02845 0 0.0825"
                                        quat="-3.67321e-06 -1 0 0">
                                        <geom type="mesh" group="1" pos="0.04181 0.01149 0.07402"
                                            euler="0 1.919 1.57"
                                            density="2.83" rgba="0.898039 0.917647 0.929412 1"
                                            mesh="dabai" />
                                        <camera name="right_wrist" pos="-0.08181 0.01149 0.16402"
                                            euler="0 -1.121 -1.57" fovy="41" mode="fixed" />
                                        <inertial pos="0.0471798 0.00010297 -0.000138511"
                                            quat="0.495436 0.504523 -0.504523 0.495436"
                                            mass="0.462245"
                                            diaginertia="0.000910182 0.00068 0.000359818" />
                                        <joint name="fr_joint6" pos="0 0 0" axis="1 0 0"
                                            limited="true"
                                            range="-3.14158 3.14158" damping="0.1" />
                                        <geom type="mesh" group="1" density="2.83"
                                            rgba="0.898039 0.917647 0.929412 1"
                                            mesh="link6" />
                                        <body name="right_hand" pos="0.073574 0 0">
                                            <!-- This camera points out from the eef. -->
                                            <camera mode="fixed" name="eye_in_hand" pos="0.05 0 0"
                                                quat="0 0.707108 0.707108 0" fovy="75" />
                                            <!-- to add gripper -->
                                        </body>
                                    </body>
                                </body>
                            </body>
                        </body>
                    </body>
                </body>
                <body name="fl_link1" pos="0.233 0.3 0.8212">
                    <site name="left_center" pos="0 0 0" size="0.01" rgba="1 0.3 0.3 1" group="2" />
                    <inertial pos="0.00609525 -0.00429682 0.017959"
                        quat="0.680193 0.680193 -0.193229 0.193229" mass="0.0608351"
                        diaginertia="8.61803e-05 6.38197e-05 3e-05" />
                    <joint name="fl_joint1" pos="0 0 0" axis="0 0 1" limited="true"
                        range="-3.14158 3.14158"
                        damping="0.1" />
                    <geom type="mesh" group="1" density="2.83" rgba="0.752941 0.752941 0.752941 1"
                        mesh="link1" />
                    <body name="fl_link2" pos="0.02 0 0.0402">
                        <inertial pos="-0.132382 0.00220381 0.00011179" quat="0 0.706195 0 0.708017"
                            mass="1.07333" diaginertia="0.0160201 0.01596 0.000499897" />
                        <joint name="fl_joint2" pos="0 0 0" axis="0 1 0" limited="true"
                            range="0 3.14158"
                            damping="0.1" />
                        <geom type="mesh" group="1" density="2.83"
                            rgba="0.752941 0.752941 0.752941 1"
                            mesh="link2" />
                        <body name="fl_link3" pos="-0.264 0 0" quat="-3.67321e-06 -1 0 0">
                            <inertial pos="0.187203 -0.000305676 -0.0514833"
                                quat="0.269626 0.618013 0.251786 0.694238" mass="0.499405"
                                diaginertia="0.00388848 0.00385541 0.000286113" />
                            <joint name="fl_joint3" pos="0 0 0" axis="0 1 0" limited="true"
                                range="0 3.14158"
                                damping="0.1" />
                            <geom type="mesh" group="1" density="2.83"
                                rgba="0.752941 0.752941 0.752941 1"
                                mesh="link3" />
                            <body name="fl_link4" pos="0.245 0 -0.056">
                                <inertial pos="0.0388885 0.00295169 -0.0353283"
                                    quat="0.913916 -0.0752199 0.315785 -0.243679" mass="0.0809713"
                                    diaginertia="0.000184798 0.000152076 5.31251e-05" />
                                <joint name="fl_joint4" pos="0 0 0" axis="0 1 0" limited="true"
                                    range="-2 1.67" damping="0.1" />
                                <geom type="mesh" group="1" density="2.83"
                                    rgba="0.898039 0.917647 0.929412 1"
                                    mesh="link4" />
                                <body name="fl_link5" pos="0.06575 -0.001 -0.0825">
                                    <inertial pos="0.00289957 3.15827e-05 0.0526189"
                                        quat="0.998829 0 -0.0483866 0" mass="0.602357"
                                        diaginertia="0.000724856 0.00069 0.000205144" />
                                    <joint name="fl_joint5" pos="0 0 0" axis="0 0 1" limited="true"
                                        range="-1.5708 1.5708" damping="0.1" />
                                    <geom type="mesh" group="1" density="2.83"
                                        rgba="0.752941 0.752941 0.752941 1"
                                        mesh="link5" />
                                    <body name="fl_link6" pos="0.02845 0 0.0825"
                                        quat="-3.67321e-06 -1 0 0">
                                        <geom type="mesh" group="1" pos="0.04181 0.01149 0.07402"
                                            euler="0 1.919 1.57"
                                            density="2.83" rgba="0.898039 0.917647 0.929412 1"
                                            mesh="dabai" />
                                        <camera name="left_wrist" pos="-0.08181 0.01149 0.16402"
                                            euler="0 -1.121 -1.57" fovy="41" mode="fixed" />
                                        <inertial pos="0.0471798 0.00010297 -0.000138511"
                                            quat="0.495436 0.504523 -0.504523 0.495436"
                                            mass="0.462245"
                                            diaginertia="0.000910182 0.00068 0.000359818" />
                                        <joint name="fl_joint6" pos="0 0 0" axis="1 0 0"
                                            limited="true"
                                            range="-3.14158 3.14158" damping="0.1" />
                                        <geom type="mesh" group="1" density="2.83"
                                            rgba="0.898039 0.917647 0.929412 1"
                                            mesh="link6" />

                                    </body>
                                </body>
                            </body>
                        </body>
                    </body>
                </body>
            </body>
        </body>
    </worldbody>

    <actuator>
        <motor name="fr_joint1" ctrllimited="true" ctrlrange="-80.0 80.0" joint="fr_joint1" />
        <motor name="fr_joint2" ctrllimited="true" ctrlrange="-80.0 80.0" joint="fr_joint2" />
        <motor name="fr_joint3" ctrllimited="true" ctrlrange="-80.0 80.0" joint="fr_joint3" />
        <motor name="fr_joint4" ctrllimited="true" ctrlrange="-12.0 12.0" joint="fr_joint4" />
        <motor name="fr_joint5" ctrllimited="true" ctrlrange="-12.0 12.0" joint="fr_joint5" />
        <motor name="fr_joint6" ctrllimited="true" ctrlrange="-12.0 12.0" joint="fr_joint6" />
        
        <motor name="fl_joint1" ctrllimited="true" ctrlrange="-80.0 80.0" joint="fl_joint1" />
        <motor name="fl_joint2" ctrllimited="true" ctrlrange="-80.0 80.0" joint="fl_joint2" />
        <motor name="fl_joint3" ctrllimited="true" ctrlrange="-80.0 80.0" joint="fl_joint3" />
        <motor name="fl_joint4" ctrllimited="true" ctrlrange="-12.0 12.0" joint="fl_joint4" />
        <motor name="fl_joint5" ctrllimited="true" ctrlrange="-12.0 12.0" joint="fl_joint5" />
        <motor name="fl_joint6" ctrllimited="true" ctrlrange="-12.0 12.0" joint="fl_joint6" />
    </actuator>
</mujoco>